Workbook
Name TM1REBUILDOPTION: 0
Name TM1RPTDATARNG1: 'Category Sales'!$31:$43
Name TM1RPTDATARNG1: 'Performance Summary'!$35:$39
Name TM1RPTDATARNG1: 'Performance Summary by Month'!$40:$44
Name TM1RPTDATARNG1: 'Store Sales'!$37:$174
Name TM1RPTDATARNG2: 'Item Sales'!$33:$62
Name TM1RPTDATARNG3: 'Top 20'!$28:$47
Name TM1RPTDATARNG4: 'New Product YTD'!$32:$43
Name TM1RPTDATARNG5: 'New Product Launch Month'!$32:$32
Name TM1RPTDATARNGARPT1: 'Store Sales'!$192:$221
Name TM1RPTDATARNGARPT2: 'Performance Summary'!$71:$90
Name TM1RPTDATARNGARPT2: 'Performance Summary by Month'!$69:$88
Name TM1RPTFMTIDCOL: 'Category Sales'!$A$1:$A$8
Name TM1RPTFMTIDCOL: 'Item Sales'!$A$1:$A$9
Name TM1RPTFMTIDCOL: 'New Product Launch Month'!$A$1:$A$9
Name TM1RPTFMTIDCOL: 'New Product YTD'!$A$1:$A$9
Name TM1RPTFMTIDCOL: 'Performance Summary'!$A$1:$A$11
Name TM1RPTFMTIDCOL: 'Performance Summary by Month'!$A$1:$A$13
Name TM1RPTFMTIDCOL: 'Store Sales'!$A$1:$A$14
Name TM1RPTFMTIDCOL: 'Top 20'!$A$1:$A$9
Name TM1RPTFMTRNG: 'Category Sales'!$C$1:$AG$8
Name TM1RPTFMTRNG: 'Item Sales'!$B$1:$AH$9
Name TM1RPTFMTRNG: 'New Product Launch Month'!$B$1:$L$9
Name TM1RPTFMTRNG: 'New Product YTD'!$B$1:$L$9
Name TM1RPTFMTRNG: 'Performance Summary'!$C$1:$L$11
Name TM1RPTFMTRNG: 'Performance Summary by Month'!$C$1:$T$13
Name TM1RPTFMTRNG: 'Store Sales'!$D$1:$AG$14
Name TM1RPTFMTRNG: 'Top 20'!$D$1:$J$9

Sheet Master
A22: BRAND PERFORMANCE REPORT
A24: MERCI
A25: YTD 2025.M12

Sheet Performance Summary
A1: [Begin Format Range]
A2: =0 -> 0
A3: =1 -> 1
A4: =2 -> 2
A5: =3 -> 3
A6: D
A7: N
A8: G
A9: H
A10: J
A11: [End Format Range]
C12: Mecca:RPT Item Store Sales Monthly:1
C13: Mecca:RPT Item Store Sales Monthly:ARPT2
C15: MECCA BRANDS BRAND PERFORMANCE REPORT | L15: =D24 -> MERCI
C18: Currency | D18: Report AUD
C19: Company | D19: Mecca Concept Consolidated Excl Intl | I19: CUBE: | J19: Mecca:CTL Retail Calendar
C20: RPT Item Store Sales Monthly Measure | D20: Sales Incl GST | I20: Weeks in Month
C21: DCS | D21: All DCS
C22: Lifestage | D22: All Lifestage
C23: Item | D23: All Item
C24: Brand | D24: =Master!A24 -> MERCI
C25: Store | D25: Total Stores by Concept Excl Non Store
C26: YTD Period: | D26: =Master!A25 -> YTD 2025.M12 | F26: ="YTD "&(D27-1)&"."&RIGHT(D26,3) -> YTD 2024.M12 | G26: =MID(D26,5,8) -> 2025.M12 | H26: December
C27: Year | D27: =MID(D26,5,4) -> 2025
C28: YEAR TO DATE 5 YEAR PERFORMANCE SUMMARY | L28: =H26&" "&D27 -> December 2025
C30: YTD SALES PERFORMANCE SUMMARY
C31: BUSINESS | G31: =$D$27&" YTD" -> 2025 YTD | H31: PRIOR YEAR EQUIVALENT | I31: =$D$27-1 -> 2024 | J31: =$D$27-2 -> 2023 | K31: =$D$27-3 -> 2022 | L31: =$D$27-4 -> 2021
C32: # Weeks Elapsed | G32: 52 | I32: 52 | J32: 53 | K32: 52 | L32: 52
G33: =$D$26 -> YTD 2025.M12 | H33: =$D$26 -> YTD 2025.M12 | I33: =$D$27-1 -> 2024 | J33: =$D$27-2 -> 2023 | K33: =$D$27-3 -> 2022 | L33: =$D$27-4 -> 2021
G34: Actual | H34: LY Actual | I34: Actual | J34: Actual | K34: Actual | L34: Actual
A35: N | C35: COSMETICA | F35: AUD | G35: 775.78 | H35: 461.2 | I35: 461.2 | J35: -197.66 | K35: -100 | L35: 52.66
A36: N | C36: MAXIMA | F36: AUD | G36: 146572.96 | H36: 188381.39 | I36: 188381.39 | J36: 103774.35 | K36: 120417.57 | L36: 94302.88
A37: N | C37: MECCA | F37: AUD | G37: 280757.39 | H37: 270997.63 | I37: 270997.63 | J37: 111180.89 | K37: 120737.13 | L37: 82182.09
A38: N | C38: SIS | F38: AUD | G38: 6229.1 | H38: 10170.4 | I38: 10170.4 | J38: 5986.3 | K38: 7482.45 | L38: 4706.5
A39: N | C39: DIRECT | F39: AUD | G39: 99333.11 | H39: 79374.53 | I39: 79374.53 | J39: 58419.94 | K39: 45062.89 | L39: 34204.7
C42: CUBE: | D42: Mecca:RPT Item Store Sales Monthly
C43: Currency | D43: Report AUD
C44: Company | D44: Mecca Brands Consolidated
C45: Trading As | D45: All Trading As Excl SIGLINE
C46: DCS | D46: All DCS
...

Sheet Performance Summary by Month
A1: [Begin Format Range]
A2: =0 -> 0
A3: =1 -> 1
A4: =2 -> 2
A5: =3 -> 3
A6: D
A7: N
A8: G
A9: H
A10: J
A11: R
A12: S
A13: [End Format Range]
C14: Mecca:RPT Item Store Sales Monthly:1
C15: Mecca:RPT Item Store Sales Monthly:ARPT2
C17: MECCA BRANDS BRAND PERFORMANCE REPORT | T17: =D26 -> MERCI
C20: Currency | D20: Report AUD
C21: Company | D21: Mecca Concept Consolidated Excl Intl | I21: CUBE: | J21: Mecca:CTL Retail Calendar
C22: RPT Item Store Sales Monthly Measure | D22: Sales Incl GST | I22: Weeks in Month
C23: DCS | D23: All DCS
C24: Lifestage | D24: All Lifestage
C25: Item | D25: All Item
C26: Brand | D26: =Master!A24 -> MERCI
C27: Store | D27: Total Stores by Concept Excl Non Store
C28: YTD Period: | D28: =Master!A25 -> YTD 2025.M12 | F28: ="YTD "&(D29-1)&"."&RIGHT(D28,3) -> YTD 2024.M12 | G28: =MID(D28,5,8) -> 2025.M12 | H28: December
C29: Year | D29: =MID(D28,5,4) -> 2025
C30: YEAR TO DATE 5 YEAR PERFORMANCE SUMMARY | T30: =$H$28&" "&$D$29 -> December 2025
C32: YTD SALES PERFORMANCE SUMMARY
C33: YTD MONTH REF: | G33: 1 | H33: 1 | I33: 1 | J33: 1 | K33: 1 | L33: 1 | M33: 1 | N33: 1 | O33: 1 | P33: 1 | Q33: 1 | R33: 1 | S33: 1 | T33: 1
C34: BUSINESS | G34: JAN 2025 | H34: FEB 2025 | I34: MAR 2025 | J34: APR 2025 | K34: MAY 2025 | L34: JUN 2025 | M34: JUL 2025 | N34: AUG 2025 | O34: SEP 2025 | P34: OCT 2025 | Q34: NOV 2025 | R34: DEC 2025 | S34: ="YTD "&$D$29 -> YTD 2025 | T34: % Share
C35: Start Date | G35: 2024-12-29 | H35: 2025-01-26 | I35: 2025-02-23 | J35: 2025-03-30 | K35: 2025-04-27 | L35: 2025-05-25 | M35: 2025-06-29 | N35: 2025-07-27 | O35: 2025-08-24 | P35: 2025-09-28 | Q35: 2025-10-26 | R35: 2025-11-23
C36: End Date | G36: 2025-01-25 | H36: 2025-02-22 | I36: 2025-03-29 | J36: 2025-04-26 | K36: 2025-05-24 | L36: 2025-06-28 | M36: 2025-07-26 | N36: 2025-08-23 | O36: 2025-09-27 | P36: 2025-10-25 | Q36: 2025-11-22 | R36: 2025-12-27
C37: # Weeks Elapsed | G37: 4 | H37: 4 | I37: 5 | J37: 4 | K37: 4 | L37: 5 | M37: 4 | N37: 4 | O37: 5 | P37: 4 | Q37: 4 | R37: 5 | S37: 52
G38: =$D$29&".M01" -> 2025.M01 | H38: =$D$29&".M02" -> 2025.M02 | I38: =$D$29&".M03" -> 2025.M03 | J38: =$D$29&".M04" -> 2025.M04 | K38: =$D$29&".M05" -> 2025.M05 | L38: =$D$29&".M06" -> 2025.M06 | M38: =$D$29&".M07" -> 2025.M07 | N38: =$D$29&".M08" -> 2025.M08 | O38: =$D$29&".M09" -> 2025.M09 | P38: =$D$29&".M10" -> 2025.M10 | Q38: =$D$29&".M11" -> 2025.M11 | R38: =$D$29&".M12" -> 2025.M12 | S38: =$D$28 -> YTD 2025.M12 | T38: =$D$28 -> YTD 2025.M12
G39: Actual | H39: Actual | I39: Actual | J39: Actual | K39: Actual | L39: Actual | M39: Actual | N39: Actual | O39: Actual | P39: Actual | Q39: Actual | R39: Actual | S39: Actual | T39: % of Total Brand Sales
A40: R | C40: COSMETICA | F40: AUD | G40: 59 | H40: 91 | I40: 39 | J40: 61.92 | K40: 70 | L40: 117 | M40: 83.88 | N40: 67 | O40: 77.98 | P40: 42 | Q40: 0 | R40: 67 | S40: 775.78 | T40: 0.0014536744
A41: R | C41: MAXIMA | F41: AUD | G41: 17272.8 | H41: 14399.61 | I41: 14744.53 | J41: 14021.25 | K41: 10553.99 | L41: 13839.28 | M41: 12609.73 | N41: 10210.58 | O41: 10521.89 | P41: 6384.36 | Q41: 6462.7 | R41: 15552.24 | S41: 146572.96 | T41: 0.27465178
A42: R | C42: MECCA | F42: AUD | G42: 29761.58 | H42: 24532.76 | I42: 27571.46 | J42: 24013.93 | K42: 19009.59 | L42: 24582.28 | M42: 22441.35 | N42: 17962.7 | O42: 21366.55 | P42: 17165.58 | Q42: 15232.48 | R42: 37117.13 | S42: 280757.39 | T42: 0.52608965
A43: R | C43: SIS | F43: AUD | G43: 983 | H43: 798.7 | I43: 998.4 | J43: 652.3 | K43: 637.5 | L43: 720.4 | M43: 557.8 | N43: 403.8 | O43: 262.2 | P43: 64 | Q43: 52 | R43: 99 | S43: 6229.1 | T43: 0.011672231
A44: S | C44: DIRECT | F44: AUD | G44: 7573 | H44: 6560.93 | I44: 6503.78 | J44: 5055.85 | K44: 7661.45 | L44: 5468.29 | M44: 11851.07 | N44: 8425.71 | O44: 8077.2 | P44: 9845.35 | Q44: 8475.76 | R44: 13834.72 | S44: 99333.11 | T44: 0.18613266
...

Sheet Category Sales
A1: [Begin Format Range]
A2: =0 -> 0
A3: =1 -> 1
A4: =2 -> 2
A5: =3 -> 3
A6: D
A7: N
A8: [End Format Range]
C9: Mecca:RPT Item Store Sales Monthly:1
C11: Currency | D11: Report AUD
C12: Company | D12: Mecca Concept Consolidated Excl Intl
C13: Sales Version | D13: Actual
C14: Trading As | D14: All Trading As Excl SIGLINE
C15: Lifestage | D15: All Lifestage
C16: Item | D16: All Item
C17: Brand | D17: =Master!$A$24 -> MERCI
C18: Store | D18: Total Stores by Concept Excl Non Store
C19: YTD Period | D19: =Master!$A$25 -> YTD 2025.M12 | E19: ="YTD "&(D20-1)&"."&RIGHT(D19,3) -> YTD 2024.M12 | F19: =MID(D19,5,8) -> 2025.M12 | G19: December
C20: Year | D20: =MID(D19,5,4) -> 2025
C22: MECCA BRANDS BRAND PERFORMANCE REPORT | AG22: =$D$17 -> MERCI
C23: YEAR TO DATE PRODUCT PERFORMANCE SUMMARY | AG23: =$G$19&" "&$D$20 -> December 2025
C25: YTD CATEGORY SALES (AUD)
C26: YTD MONTH REF: | D26: 1 | E26: 1 | F26: 1 | G26: 1 | H26: 1 | I26: 1 | J26: 1 | K26: 1 | L26: 1 | M26: 1 | N26: 1 | O26: 1 | P26: 1 | Q26: 1 | R26: 1 | S26: 1 | T26: 1 | U26: 1 | V26: 1 | W26: 1 | X26: 1 | Y26: 1 | Z26: 1 | AA26: 1
D27: =$D$20&".M01" -> 2025.M01 | E27: =$D$20&".M01" -> 2025.M01 | F27: =$D$20&".M02" -> 2025.M02 | G27: =$D$20&".M02" -> 2025.M02 | H27: =$D$20&".M03" -> 2025.M03 | I27: =$D$20&".M03" -> 2025.M03 | J27: =$D$20&".M04" -> 2025.M04 | K27: =$D$20&".M04" -> 2025.M04 | L27: =$D$20&".M05" -> 2025.M05 | M27: =$D$20&".M05" -> 2025.M05 | N27: =$D$20&".M06" -> 2025.M06 | O27: =$D$20&".M06" -> 2025.M06 | P27: =$D$20&".M07" -> 2025.M07 | Q27: =$D$20&".M07" -> 2025.M07 | R27: =$D$20&".M08" -> 2025.M08 | S27: =$D$20&".M08" -> 2025.M08 | T27: =$D$20&".M09" -> 2025.M09 | U27: =$D$20&".M09" -> 2025.M09 | V27: =$D$20&".M10" -> 2025.M10 | W27: =$D$20&".M10" -> 2025.M10 | X27: =$D$20&".M11" -> 2025.M11 | Y27: =$D$20&".M11" -> 2025.M11 | Z27: =$D$20&".M12" -> 2025.M12 | AA27: =$D$20&".M12" -> 2025.M12 | AB27: =$D$19 -> YTD 2025.M12 | AC27: =$D$19 -> YTD 2025.M12 | AD27: =$E$19 -> YTD 2024.M12 | AE27: =$E$19 -> YTD 2024.M12
D28: Total Store Sales | E28: % of Total Department Sales | F28: Total Store Sales | G28: % of Total Department Sales | H28: Total Store Sales | I28: % of Total Department Sales | J28: Total Store Sales | K28: % of Total Department Sales | L28: Total Store Sales | M28: % of Total Department Sales | N28: Total Store Sales | O28: % of Total Department Sales | P28: Total Store Sales | Q28: % of Total Department Sales | R28: Total Store Sales | S28: % of Total Department Sales | T28: Total Store Sales | U28: % of Total Department Sales | V28: Total Store Sales | W28: % of Total Department Sales | X28: Total Store Sales | Y28: % of Total Department Sales | Z28: Total Store Sales | AA28: % of Total Department Sales | AB28: Total Store Sales | AC28: % of Total Department Sales | AD28: Total Store Sales | AE28: % of Total Department Sales
C29: CATEGORY | D29: JAN 2025 | F29: FEB 2025 | H29: MAR 2025 | J29: APR 2025 | L29: MAY 2025 | N29: JUN 2025 | P29: JUL 2025 | R29: AUG 2025 | T29: SEP 2025 | V29: OCT 2025 | X29: NOV 2025 | Z29: DEC 2025 | AB29: =LEFT(AC27,8) -> YTD 2025 | AD29: =LEFT(AE27,8) -> YTD 2024 | AF29: CHANGE IN | AG29: CHANGE IN
D30: $ SALES | E30: % SALES | F30: $ SALES | G30: % SALES | H30: $ SALES | I30: % SALES | J30: $ SALES | K30: % SALES | L30: $ SALES | M30: % SALES | N30: $ SALES | O30: % SALES | P30: $ SALES | Q30: % SALES | R30: $ SALES | S30: % SALES | T30: $ SALES | U30: % SALES | V30: $ SALES | W30: % SALES | X30: $ SALES | Y30: % SALES | Z30: $ SALES | AA30: % SALES | AB30: $ SALES | AC30: % SALES | AD30: $ SALES | AE30: % SALES | AF30: % SHARE | AG30: SHARE GROWTH
A31: 2 | C31: Body - Bath & Body | D31: 51.68 | E31: 0.00092867162 | F31: 77.36 | G31: 0.0016678524 | H31: 64.68 | I31: 0.0012973059 | J31: 13 | K31: 0.00029676808 | L31: 0 | M31: 0 | N31: 0 | O31: 0 | P31: 6032.24 | Q31: 0.12687745 | R31: 2099.2 | S31: 0.056628322 | T31: 3244.94 | U31: 0.080507976 | V31: 2389.03 | W31: 0.071311582 | X31: 1557.72 | Y31: 0.051540982 | Z31: 3888.56 | AA31: 0.058325405 | AB31: 19418.41 | AC31: 0.036386663 | AD31: 492.1 | AE31: 0.00089572862 | AF31: =AC31-AE31 -> 0.035490934 | AG31: =IFERROR((AB31/AD31)-1,0) -> 38.460293
A32: 2 | C32: Body - Cleanser | D32: 0 | E32: 0 | F32: 0 | G32: 0 | H32: 0 | I32: 0 | J32: 0 | K32: 0 | L32: 0 | M32: 0 | N32: 0 | O32: 0 | P32: 0 | Q32: 0 | R32: 0 | S32: 0 | T32: 36 | U32: 0.00089317126 | V32: 1130.4 | W32: 0.033741984 | X32: 921.6 | Y32: 0.030493393 | Z32: 1759.2 | AA32: 0.026386645 | AB32: 3847.2 | AC32: 0.0072089718 | AD32: 0 | AE32: 0 | AF32: =AC32-AE32 -> 0.0072089718 | AG32: =IFERROR((AB32/AD32)-1,0) -> 0
A33: 2 | C33: Body - Personal Care | D33: 8252.32 | E33: 0.14829132 | F33: 8173.25 | G33: 0.17621219 | H33: 7413.91 | I33: 0.14870298 | J33: 5780.85 | K33: 0.13196706 | L33: 4638.6 | M33: 0.12228554 | N33: 5939.03 | O33: 0.13278326 | P33: 3807.13 | Q33: 0.080076216 | R33: 3806.39 | S33: 0.10268173 | T33: 2972.24 | U33: 0.073742204 | V33: 3128.31 | W33: 0.093378792 | X33: 3458.78 | Y33: 0.11444221 | Z33: 10392.72 | AA33: 0.1558828 | AB33: 67763.53 | AC33: 0.12697686 | AD33: 40740.99 | AE33: 0.074157429 | AF33: =AC33-AE33 -> 0.052819431 | AG33: =IFERROR((AB33/AD33)-1,0) -> 0.66327647
A34: 2 | C34: Body - Hand & Foot Care | D34: 19938.1 | E34: 0.35828072 | F34: 15628.99 | G34: 0.33695513 | H34: 17438.48 | I34: 0.34976875 | J34: 14503.3 | K34: 0.33108589 | L34: 10620.52 | M34: 0.27998449 | N34: 11821.2 | O34: 0.26429526 | P34: 5131.01 | Q34: 0.10792168 | R34: 2579.38 | S34: 0.069581727 | T34: 2652.4 | U34: 0.065806874 | V34: 1743.63 | W34: 0.052046653 | X34: 1026.45 | Y34: 0.033962613 | Z34: 2898.74 | AA34: 0.043478867 | AB34: 105982.2 | AC34: 0.19859188 | AD34: 223175.7 | AE34: 0.40622813 | AF34: =AC34-AE34 -> -0.20763624 | AG34: =IFERROR((AB34/AD34)-1,0) -> -0.52511765
A35: 2 | C35: Body - Body Packs & Sets | D35: 1366.74 | E35: 0.024559842 | F35: 1643.4 | G35: 0.035431085 | H35: 1951.14 | I35: 0.039134592 | J35: 1667.58 | K35: 0.03806804 | L35: 1856.43 | M35: 0.048940316 | N35: 2375.19 | O35: 0.053103868 | P35: 2675.73 | Q35: 0.056279227 | R35: 2064 | S35: 0.055678762 | T35: 3449.6 | U35: 0.085585655 | V35: 3183.4 | W35: 0.095023207 | X35: 4863.01 | Y35: 0.1609046 | Z35: 6103.57 | AA35: 0.091548849 | AB35: 33199.79 | AC35: 0.062210529 | AD35: 22530.77 | AE35: 0.041010883 | AF35: =AC35-AE35 -> 0.021199647 | AG35: =IFERROR((AB35/AD35)-1,0) -> 0.47353109
A36: 2 | C36: Body - Moisturiser | D36: 0 | E36: 0 | F36: 0 | G36: 0 | H36: 0 | I36: 0 | J36: 0 | K36: 0 | L36: 0 | M36: 0 | N36: 0 | O36: 0 | P36: 1005.25 | Q36: 0.021143648 | R36: 987.4 | S36: 0.026636245 | T36: 811.32 | U36: 0.020129103 | V36: 819.65 | W36: 0.024466222 | X36: 337.93 | Y36: 0.011181242 | Z36: 914.3 | AA36: 0.013713796 | AB36: 4875.85 | AC36: 0.0091364798 | AD36: 0 | AE36: 0 | AF36: =AC36-AE36 -> 0.0091364798 | AG36: =IFERROR((AB36/AD36)-1,0) -> 0
A37: 1 | C37: Body | D37: 29608.84 | E37: 0.53206055 | F37: 25523 | G37: 0.55026626 | H37: 26868.21 | I37: 0.53890363 | J37: 21964.73 | K37: 0.50141775 | L37: 17115.55 | M37: 0.45121035 | N37: 20135.42 | O37: 0.45018238 | P37: 18651.36 | Q37: 0.39229822 | R37: 11536.37 | S37: 0.31120678 | T37: 13166.5 | U37: 0.32666498 | V37: 12394.42 | W37: 0.36996844 | X37: 12165.49 | Y37: 0.40252504 | Z37: 25957.09 | AA37: 0.38933636 | AB37: 235086.98 | AC37: 0.44051139 | AD37: 286939.56 | AE37: 0.52229217 | AF37: =AC37-AE37 -> -0.08178078 | AG37: =IFERROR((AB37/AD37)-1,0) -> -0.18070907
A38: 2 | C38: Fragrance - Personal | D38: 0 | E38: 0 | F38: 0 | G38: 0 | H38: 0 | I38: 0 | J38: 0 | K38: 0 | L38: 0 | M38: 0 | N38: 0 | O38: 0 | P38: 6063.1 | Q38: 0.12752654 | R38: 4840.8 | S38: 0.13058612 | T38: 4558.82 | U38: 0.11310575 | V38: 2516.63 | W38: 0.075120391 | X38: 1871.3 | Y38: 0.061916544 | Z38: 6174.65 | AA38: 0.092614994 | AB38: 26025.3 | AC38: 0.048766805 | AD38: 0 | AE38: 0 | AF38: =AC38-AE38 -> 0.048766805 | AG38: =IFERROR((AB38/AD38)-1,0) -> 0
A39: 1 | C39: Fragrance | D39: 0 | E39: 0 | F39: 0 | G39: 0 | H39: 0 | I39: 0 | J39: 0 | K39: 0 | L39: 0 | M39: 0 | N39: 0 | O39: 0 | P39: 6063.1 | Q39: 0.12752654 | R39: 4840.8 | S39: 0.13058612 | T39: 4558.82 | U39: 0.11310575 | V39: 2516.63 | W39: 0.075120391 | X39: 1871.3 | Y39: 0.061916544 | Z39: 6174.65 | AA39: 0.092614994 | AB39: 26025.3 | AC39: 0.048766805 | AD39: 0 | AE39: 0 | AF39: =AC39-AE39 -> 0.048766805 | AG39: =IFERROR((AB39/AD39)-1,0) -> 0
A40: 2 | C40: Skincare - Skin Accessories | D40: 4541.58 | E40: 0.081610613 | F40: 959.6 | G40: 0.020688614 | H40: 288.4 | I40: 0.0057845241 | J40: 0 | K40: 0 | L40: 3996 | M40: 0.10534494 | N40: 4099.07 | O40: 0.091645921 | P40: 3598.69 | Q40: 0.075692051 | R40: 3472.88 | S40: 0.093684912 | T40: 5141.57 | U40: 0.12756396 | V40: 4704.59 | W40: 0.14043011 | X40: 3845.74 | Y40: 0.12724573 | Z40: 5591.05 | AA40: 0.083861444 | AB40: 40239.17 | AC40: 0.075401082 | AD40: 47935.35 | AE40: 0.087252722 | AF40: =AC40-AE40 -> -0.011851641 | AG40: =IFERROR((AB40/AD40)-1,0) -> -0.16055333
A41: 2 | C41: Skincare - Treatment | D41: 21498.96 | E41: 0.38632883 | F41: 19900.4 | G41: 0.42904512 | H41: 22700.56 | I41: 0.45531184 | J41: 21840.52 | K41: 0.49858225 | L41: 16820.98 | M41: 0.44344472 | N41: 20492.76 | O41: 0.4581717 | P41: 19230.68 | Q41: 0.40448319 | R41: 17219.74 | S41: 0.46452219 | T41: 17438.93 | U41: 0.43266531 | V41: 13885.65 | W41: 0.41448105 | X41: 12340.41 | Y41: 0.40831269 | Z41: 28947.3 | AA41: 0.4341872 | AB41: 232316.89 | AC41: 0.43532073 | AD41: 214510.24 | AE41: 0.39045511 | AF41: =AC41-AE41 -> 0.044865616 | AG41: =IFERROR((AB41/AD41)-1,0) -> 0.083010722
A42: 1 | C42: Skincare | D42: 26040.54 | E42: 0.46793945 | F42: 20860 | G42: 0.44973374 | H42: 22988.96 | I42: 0.46109637 | J42: 21840.52 | K42: 0.49858225 | L42: 20816.98 | M42: 0.54878965 | N42: 24591.83 | O42: 0.54981762 | P42: 22829.37 | Q42: 0.48017524 | R42: 20692.62 | S42: 0.5582071 | T42: 22580.5 | U42: 0.56022927 | V42: 18590.24 | W42: 0.55491117 | X42: 16186.15 | Y42: 0.53555842 | Z42: 34538.35 | AA42: 0.51804865 | AB42: 272556.06 | AC42: 0.51072181 | AD42: 262445.59 | AE42: 0.47770783 | AF42: =AC42-AE42 -> 0.033013975 | AG42: =IFERROR((AB42/AD42)-1,0) -> 0.038524061
A43: 0 | C43: Total DCS | D43: 55649.38 | E43: 1 | F43: 46383 | G43: 1 | H43: 49857.17 | I43: 1 | J43: 43805.25 | K43: 1 | L43: 37932.53 | M43: 1 | N43: 44727.25 | O43: 1 | P43: 47543.83 | Q43: 1 | R43: 37069.79 | S43: 1 | T43: 40305.82 | U43: 1 | V43: 33501.29 | W43: 1 | X43: 30222.94 | Y43: 1 | Z43: 66670.09 | AA43: 1 | AB43: 533668.34 | AC43: 1 | AD43: 549385.15 | AE43: 1 | AF43: =AC43-AE43 -> 0 | AG43: =IFERROR((AB43/AD43)-1,0) -> -0.028607999

Sheet Top 20
A1: [Begin Format Range]
A2: =0 -> 0
A3: =1 -> 1
A4: =2 -> 2
A5: =3 -> 3
A6: D
A7: N
A8: P
A9: [End Format Range]
D10: Mecca:RPT Item Store Sales Monthly:3
D11: Filter: | E11: Order(TOPCOUNT(Distinct({ }), 20, ([RPT Item Store Sales Monthly Measure].[Total Units Sold])), ([RPT Item Store Sales Monthly Measure].[Total Units Sold]), BDESC)
D12: Currency | E12: Report AUD
D13: Company | E13: Mecca Concept Consolidated Excl Intl
D14: Month | E14: =Master!A25 -> YTD 2025.M12 | H14: =MID(E14,5,8) -> 2025.M12 | I14: December
D15: Sales Version | E15: Actual | I15: =MID(E14,5,4) -> 2025
D16: Trading As | E16: All Trading As Excl SIGLINE
D17: Lifestage | E17: All Lifestage
D18: DCS | E18: All DCS
D19: Brand | E19: =Master!A24 -> MERCI
D20: Store | E20: Total Stores by Concept Excl Non Store
C22: MECCA BRANDSBRAND PERFORMANCE REPORT | J22: =E19 -> MERCI
C23: YEAR TO DATE TOP 20 ITEMS | J23: =$I$14&" "&$I$15 -> December 2025
C25: RANK | E25: PRODUCT DESCRIPTION | F25: VENDOR ITEM CODE | G25: TOTAL UNITS SOLD | H25: % UNITS SOLD | I25: TOTAL $ SALES (AUD) | J25: % SALES
G26: Total Units Sold | H26: % of Total Brand Units | I26: Total Store Sales | J26: % of Total Brand Sales
E27: TOP 20 ITEMS TOTAL | G27: =SUM($G$28:$G$103) -> 46252 | H27: =SUM($H$28:$H$103) -> 0.9862044 | I27: =SUM($I$28:$I$103) -> 517830.54 | J27: =SUM($J$28:$J$103) -> 0.97032277
A28: N | C28: =C27+1 -> 1 | D28: I-060352 | E28: SPOT PATCHES | F28: MH-PATCH-24-22 | G28: 17741 | H28: 0.37828099 | I28: 232316.89 | J28: 0.43532073
A29: N | C29: =C28+1 -> 2 | D29: I-040423 | E29: HAND CLEANSING FLOWER POWER | F29: MH-GEL-30-FP-EU-19 | G29: 6093 | H29: 0.12991748 | I29: 32407.09 | J29: 0.06072515
A30: N | C30: =C29+1 -> 3 | D30: I-040425 | E30: HAND CLEANSING UNICORN | F30: MH-GEL-30-UE-EU-19 | G30: 4165 | H30: 0.088807864 | I30: 21409.7 | J30: 0.040117988
A31: N | C31: =C30+1 -> 4 | D31: I-060353 | E31: BLOTTING PAPER | F31: MH-PM-50-22 | G31: 2737 | H31: 0.058359453 | I31: 40239.17 | J31: 0.075401082
A32: N | C32: =C31+1 -> 5 | D32: I-040426 | E32: HAND CLEANSING NAMASTE | F32: MH-GEL-30-NA-EU-19 | G32: 2348 | H32: 0.050065033 | I32: 11986.43 | J32: 0.022460448
A33: N | C33: =C32+1 -> 6 | D33: I-044748 | E33: HAND CLEANS GLITTER FEVER | F33: MH-GEL-30-GF-EU-19 | G33: 2297 | H33: 0.04897759 | I33: 12374.43 | J33: 0.023187491
A34: N | C34: =C33+1 -> 7 | D34: I-054934 | E34: GLITTER SET | F34: MH-KIT-GLI-20 | G34: 1910 | H34: 0.040725815 | I34: 31395.38 | J34: 0.058829385
A35: N | C35: =C34+1 -> 8 | D35: I-066437 | E35: DEODORANT MOON 55G | F35: MH-DEO-MOON-55 | G35: 1828 | H35: 0.038977377 | I35: 30243.22 | J35: 0.056670441
A36: N | C36: =C35+1 -> 9 | D36: I-040427 | E36: HAND CLEANSING HELLO SUN | F36: MH-GEL-30-HS-EU-19 | G36: 1794 | H36: 0.038252415 | I36: 9323.09 | J36: 0.01746982
A37: N | C37: =C36+1 -> 10 | D37: I-066438 | E37: DEODORANT SUN 55G | F37: MH-DEO-SUN-55 | G37: 1155 | H37: 0.024627391 | I37: 19445.75 | J37: 0.036437893
A38: N | C38: =C37+1 -> 11 | D38: I-066436 | E38: DEODORANT EARTH 55G | F38: MH-DEO-EARTH-55 | G38: 1073 | H38: 0.022878953 | I38: 18074.56 | J38: 0.033868526
A39: N | C39: =C38+1 -> 12 | D39: I-048194 | E39: CLEANSING SPRAY PURIFYING | F39: MH-SPRAY-50-PUR-US | G39: 557 | H39: 0.011876586 | I39: 9947.18 | J39: 0.018639254
... A47: P | C47: =C46+1 -> 20 | D47: I-075725 | E47: FRAGRANCE MIST SUN 100ML | F47: MH-BODYMIST-SU | G47: 207 | H47: 0.0044137402 | I47: 5827.71 | J47: 0.010920097

Sheet New Product Launch Month
A1: [Begin Format Range]
A2: =0 -> 0
A3: =1 -> 1
A4: =2 -> 2
A5: =3 -> 3
A6: D
A7: N
A8: P
A9: [End Format Range]
B10: Mecca:RPT Item Store Sales Monthly:5
B11: Filter Reference | C11: Order(Distinct({ }), ([RPT Item Store Sales Monthly Measure].[Total Units Sold]), BDESC)
B12: Currency | C12: Report AUD
B13: Company | C13: Mecca Concept Consolidated Excl Intl
B14: Month | C14: =Master!A25 -> YTD 2025.M12 | E14: =MID(C14,5,8) -> 2025.M12 | F14: December
B15: Sales Version | C15: Actual | F15: =MID(C14,5,4) -> 2025
B16: Trading As | C16: All Trading As Excl SIGLINE
B17: Lifestage | C17: All Lifestage
B18: DCS | C18: All DCS
B19: Brand | C19: =Master!A24 -> MERCI
B20: Store | C20: Total Stores by Concept Excl Non Store
F21: =C32
B22: ="{TM1FILTERBYPATTERN({FILTER({TM1DRILLDOWNMEMBER({[Item].[All Item]},ALL,RECURSIVE)},[Item].[Launch Month]='"&$E$14&"')}, "&"'I-*'"&")}" -> {TM1FILTERBYPATTERN({FILTER({TM1DRILLDOWNMEMBER({[Item].[All Item]},ALL,RECURSIVE)},[Item].[Launch Month]='2025.M12')}, 'I-*')}
E25: MECCA BRANDS BRAND PERFORMANCE REPORT | L25: =C19 -> MERCI
E26: NEW PRODUCT PERFORMANCE REPORT | L26: =$F$14&" "&$F$15 -> December 2025
E28: ="PERFORMANCE OF NEW ITEMS LAUNCHED IN "&UPPER(L26)&" (RANKED BY UNITS SOLD)" -> PERFORMANCE OF NEW ITEMS LAUNCHED IN DECEMBER 2025 (RANKED BY UNITS SOLD)
I29: Total Units Sold | J29: % of Total Brand Sales | K29: Total Store Sales | L29: % of Total Brand Units
E30: LAUNCH MONTH | F30: LAUNCH DATE | G30: VENDOR ITEM CODE | H30: ITEM DESCRIPTION | I30: TOTAL UNITS SOLD | J30: % UNITS SOLD | K30: TOTAL $ SALES (AUD) | L30: % SALES
H31: NEW ITEMS TOTAL | I31: =SUM($I$32:$I$222) -> 0 | J31: =SUM($J$32:$J$222) -> 0 | K31: =SUM($K$32:$GK$222) -> 0 | L31: =SUM($L$32:$L$222) -> 0
A32: P | F32: =C32

Sheet New Product YTD
A1: [Begin Format Range]
A2: =0 -> 0
A3: =1 -> 1
A4: =2 -> 2
A5: =3 -> 3
A6: D
A7: N
A8: P
A9: [End Format Range]
B10: Mecca:RPT Item Store Sales Monthly:4
B11: Filter Reference | C11: Order(Distinct({ }), ([RPT Item Store Sales Monthly Measure].[Total Units Sold]), BDESC)
B12: Currency | C12: Report AUD
B13: Company | C13: Mecca Concept Consolidated Excl Intl
B14: Month | C14: =Master!A25 -> YTD 2025.M12 | E14: =MID(C14,5,4) -> 2025 | F14: =MID(C14,5,8) -> 2025.M12 | G14: 0 | H14: December
B15: Sales Version | C15: Actual
B16: Trading As | C16: All Trading As Excl SIGLINE
B17: Lifestage | C17: All Lifestage
B18: DCS | C18: All DCS
B19: Brand | C19: =Master!A24 -> MERCI
B20: Store | C20: Total Stores by Concept Excl Non Store
B23: ="{TM1FILTERBYPATTERN({FILTER({TM1DRILLDOWNMEMBER({[Item].[All Item]},ALL,RECURSIVE)},[Item].[Launch Year]='"&$E$14&"')}, "&"'I-*'"&")}" -> {TM1FILTERBYPATTERN({FILTER({TM1DRILLDOWNMEMBER({[Item].[All Item]},ALL,RECURSIVE)},[Item].[Launch Year]='2025')}, 'I-*')}
E25: MECCA BRANDS BRAND PERFORMANCE REPORT | L25: =C19 -> MERCI
E26: NEW PRODUCT PERFORMANCE REPORT | L26: =$H$14&" "&$E$14 -> December 2025
E28: ="PERFORMANCE OF NEW ITEMS LAUNCHED YTD "&UPPER(L26)&" (RANKED BY UNITS SOLD)" -> PERFORMANCE OF NEW ITEMS LAUNCHED YTD DECEMBER 2025 (RANKED BY UNITS SOLD)
I29: Total Units Sold | J29: % of Total Brand Sales | K29: Total Store Sales | L29: % of Total Brand Units
E30: LAUNCH MONTH | F30: LAUNCH DATE | G30: VENDOR ITEM CODE | H30: ITEM DESCRIPTION | I30: TOTAL UNITS SOLD | J30: % UNITS SOLD | K30: TOTAL $ SALES (AUD) | L30: % SALES
H31: YTD NEW ITEMS TOTAL | I31: =SUM($I$32:$I$451) -> 2754 | J31: =SUM($J$32:$J$451) -> 0.10518938 | K31: =SUM($K$32:$K$451) -> 56136.24 | L31: =SUM($L$32:$L$451) -> 0.058721934
A32: N | B32: I-075721 | C32: 2025-07-01 | E32: JULY | F32: =C32 -> 2025-07-01 | G32: MH-BSERUM-90-BZ | H32: BIKINI ARMPITS SERUM 90ML | I32: 481 | J32: 0.025000396 | K32: 13341.92 | L32: 0.010256082
A33: N | B33: I-075723 | C33: 2025-06-26 | E33: JUNE | F33: =C33 -> 2025-06-26 | G33: MH-BODYMIST-MO | H33: FRAGRANCE MIST MOON 100ML | I33: 479 | J33: 0.02504683 | K33: 13366.7 | L33: 0.010213437
A34: N | B34: I-075728 | C34: 2025-09-30 | E34: OCTOBER | F34: =C34 -> 2025-09-30 | G34: MH-GEL-30-UE-US-19 | H34: N HAND SANITISER - UNICORN | I34: 403 | J34: 0.0045084181 | K34: 2406 | L34: 0.0085929338
A35: N | B35: I-075729 | C35: 2025-09-30 | E35: OCTOBER | F35: =C35 -> 2025-09-30 | G35: MH-GEL-30-NA-US-19 | H35: N HAND SANITISER - NAMASTE | I35: 293 | J35: 0.0032851865 | K35: 1753.2 | L35: 0.006247468
A36: N | B36: I-075724 | C36: 2025-06-26 | E36: JUNE | F36: =C36 -> 2025-06-26 | G36: MH-BODYMIST-EA | H36: FRAGRANCE MIST EARTH 100ML | I36: 243 | J36: 0.012799879 | K36: 6830.89 | L36: 0.0051813472
A37: N | B37: I-075727 | C37: 2025-09-30 | E37: OCTOBER | F37: =C37 -> 2025-09-30 | G37: MH-GEL-30-HS-US-19 | H37: N HAND SANITISER - HELLO SUN | I37: 241 | J37: 0.0027005537 | K37: 1441.2 | L37: 0.0051387023
A38: N | B38: I-075725 | C38: 2025-06-26 | E38: JUNE | F38: =C38 -> 2025-06-26 | G38: MH-BODYMIST-SU | H38: FRAGRANCE MIST SUN 100ML | I38: 207 | J38: 0.010920097 | K38: 5827.71 | L38: 0.0044137402
A39: N | B39: I-075719 | C39: 2025-06-26 | E39: JUNE | F39: =C39 -> 2025-06-26 | G39: MH-BSERUM-90-BB | H39: BODY SERUM BACK BUTT 90ML | I39: 174 | J39: 0.0091364798 | K39: 4875.85 | L39: 0.0037101004
A40: N | B40: I-075722 | C40: 2025-07-01 | E40: JULY | F40: =C40 -> 2025-07-01 | G40: MH-BSERUM-90-BH | H40: BOOBS HIPS SERUM 90ML | I40: 115 | J40: 0.0060400435 | K40: 3223.38 | L40: 0.0024520779
A41: N | B41: I-075720 | C41: 2025-07-01 | E41: JULY | F41: =C41 -> 2025-07-01 | G41: MH-BSERUM-90-KE | H41: KNEES ELBOWS SERUM 90ML | I41: 95 | J41: 0.0049588664 | K41: 2646.39 | L41: 0.0020256295
A42: N | B42: I-075730 | C42: 2025-09-30 | E42: OCTOBER | F42: =C42 -> 2025-09-30 | G42: MH-SPRAY-50-ENE-US | H42: N HAND SANITIZER SPRAY ENERG | I42: 22 | J42: 0.00078325801 | K42: 418 | L42: 0.00046909316
A43: P | B43: I-075726 | C43: 2025-09-30 | E43: OCTOBER | F43: =C43 -> 2025-09-30 | G43: MH-GEL-30-FP-US-19 | H43: N HAND SANITISER - FLOWER PO | I43: 1 | J43: 9.3691149e-06 | K43: 5 | L43: 2.1322416e-05

Sheet Operation Summary
C3: Sales Version | D3: ="Actual" -> Actual
C4: Currency | D4: ="Report AUD" -> Report AUD
C5: Company | D5: ="Mecca Concept Consolidated Excl Intl" -> Mecca Concept Consolidated Excl Intl
C6: Trading As | D6: ="All Trading As" -> All Trading As
C7: Store | D7: ="Total Stores by Concept Excl Non Store" -> Total Stores by Concept Excl Non Store
C8: Brands | D8: =Master!A24 -> MERCI
C9: DCS | D9: ="All DCS" -> All DCS
C10: Lifestage | D10: ="All Lifestage" -> All Lifestage
C11: Item | D11: ="All Item" -> All Item | E11: All I Items | F11: All Tester Items | G11: All Fulfillment Items
C12: Brand Currency | D12: EUR
C18: YTD Period: | D18: =Master!A25 -> YTD 2025.M12 | E18: =MID(D18,5,8) -> 2025.M12 | F18: 2025-12-27 | G18: ="YTD "&$F$18 -> YTD 2025-12-27 | H18: ="YTD "&(E19-1)&"."&RIGHT(D18,3) -> YTD 2024.M12 | I18: December
C19: Year | E19: =MID(D18,5,4) -> 2025
D20: All Calendar Day | E20: =$E$19&".M01" -> 2025.M01 | F20: =$E$19&".M02" -> 2025.M02 | G20: =$E$19&".M03" -> 2025.M03 | H20: =$E$19&".M04" -> 2025.M04 | I20: =$E$19&".M05" -> 2025.M05 | J20: =$E$19&".M06" -> 2025.M06 | K20: =$E$19&".M07" -> 2025.M07 | L20: =$E$19&".M08" -> 2025.M08 | M20: =$E$19&".M09" -> 2025.M09 | N20: =$E$19&".M10" -> 2025.M10 | O20: =$E$19&".M11" -> 2025.M11 | P20: =$E$19&".M12" -> 2025.M12 | Q20: =E19 -> 2025
D21: 2019 CAL | E21: =CONCATENATE($E$19,"-Jan") -> 2025-Jan | F21: =CONCATENATE($E$19,"-Feb") -> 2025-Feb | G21: =CONCATENATE($E$19,"-Mar") -> 2025-Mar | H21: =CONCATENATE($E$19,"-Apr") -> 2025-Apr | I21: =CONCATENATE($E$19,"-May") -> 2025-May | J21: =CONCATENATE($E$19,"-Jun") -> 2025-Jun | K21: =CONCATENATE($E$19,"-Jul") -> 2025-Jul | L21: =CONCATENATE($E$19,"-Aug") -> 2025-Aug | M21: =CONCATENATE($E$19,"-Sep") -> 2025-Sep | N21: =CONCATENATE($E$19,"-Oct") -> 2025-Oct | O21: =CONCATENATE($E$19,"-Nov") -> 2025-Nov | P21: =CONCATENATE($E$19,"-Dec") -> 2025-Dec | Q21: =$E$19 -> 2025
C23: MECCA BRANDS BRAND PERFORMANCE REPORT | P23: =$D$8 -> MERCI
C24: YEAR TO DATE OPERATIONAL PERFORMANCE SUMMARY | P24: =I18&" "&E19 -> December 2025
C27: Mecca:RPT Item Store Sales Monthly
C28: YTD MONTH REF: | E28: 1 | F28: 1 | G28: 1 | H28: 1 | I28: 1 | J28: 1 | K28: 1 | L28: 1 | M28: 1 | N28: 1 | O28: 1 | P28: 1 | Q28: 1
C29: Item Sales
E30: JAN 2025 | F30: FEB 2025 | G30: MAR 2025 | H30: APR 2025 | I30: MAY 2025 | J30: JUN 2025 | K30: JUL 2025 | L30: AUG 2025 | M30: SEP 2025 | N30: OCT 2025 | O30: NOV 2025 | P30: DEC 2025 | Q30: YTD TOTAL
A31: Sales Incl GST | C31: Total Sales ($ at Retail) | D31: AUD | E31: 55649.38 | F31: 46383 | G31: 49857.17 | H31: 43805.25 | I31: 37932.53 | J31: 44727.25 | K31: 47543.83 | L31: 37069.79 | M31: 40305.82 | N31: 33501.29 | O31: 30222.94 | P31: 66670.09 | Q31: 533668.34
C33: Mecca:RPT Item Orders
C35: CALENDAR YTD ORDERS AND FULFILMENT SUMMARY - LIVE
E36: JAN 2025 | F36: FEB 2025 | G36: MAR 2025 | H36: APR 2025 | I36: MAY 2025 | J36: JUN 2025 | K36: JUL 2025 | L36: AUG 2025 | M36: SEP 2025 | N36: OCT 2025 | O36: NOV 2025 | P36: DEC 2025 | Q36: YTD TOTAL
A37: Original Order Direct Cost | C37: ORDERED | D37: =D12 -> EUR | E37: 0 | F37: 8780.5 | G37: 0 | H37: 2787 | I37: 17544 | J37: 2040 | K37: 19452.25 | L37: 11889 | M37: 32515.28 | N37: 5343 | O37: 14704.4 | P37: 22310 | Q37: =SUM(E37:P37) -> 137365.43
A38: Accepted Order Direct Cost | C38: INVOICED | D38: =D12 -> EUR | E38: 0 | F38: 4825.5 | G38: 0 | H38: 2787 | I38: 11904 | J38: 2040 | K38: 4328.5 | L38: 7815 | M38: 26679.52 | N38: 5343 | O38: 13424.4 | P38: 0 | Q38: =SUM(E38:P38) -> 79146.92
C39: FULFILMENT RATE | D39: % | E39: =IF(E37=0,"N/A",IF(ISERROR(E38/E37),0,(E38/E37))) -> N/A | F39: =IF(F37=0,"N/A",IF(ISERROR(F38/F37),0,(F38/F37))) -> 0.54957007 | G39: =IF(G37=0,"N/A",IF(ISERROR(G38/G37),0,(G38/G37))) -> N/A | H39: =IF(H37=0,"N/A",IF(ISERROR(H38/H37),0,(H38/H37))) -> 1 | I39: =IF(I37=0,"N/A",IF(ISERROR(I38/I37),0,(I38/I37))) -> 0.67852257 | J39: =IF(J37=0,"N/A",IF(ISERROR(J38/J37),0,(J38/J37))) -> 1 | K39: =IF(K37=0,"N/A",IF(ISERROR(K38/K37),0,(K38/K37))) -> 0.22251925 | L39: =IF(L37=0,"N/A",IF(ISERROR(L38/L37),0,(L38/L37))) -> 0.65733031 | ... Q39: =IF(Q37=0,"N/A",IF(ISERROR(Q38/Q37),0,(Q38/Q37))) -> 0.57617786
E41: JAN 2025 | F41: FEB 2025 | G41: MAR 2025 | H41: APR 2025 | I41: MAY 2025 | J41: JUN 2025 | K41: JUL 2025 | L41: AUG 2025 | M41: SEP 2025 | N41: OCT 2025 | O41: NOV 2025 | P41: DEC 2025 | Q41: YTD TOTAL
A42: Original Order Quantity | C42: ORDERED | D42: UNITS | E42: 0 | F42: 4408 | G42: 0 | H42: 972 | I42: 8412 | J42: 844 | K42: 9223 | L42: 4852 | M42: 21822 | N42: 2616 | O42: 8432 | P42: 11288 | Q42: =SUM(E42:P42) -> 72869
A43: Accepted Order Quantity | C43: INVOICED | D43: UNITS | E43: 0 | F43: 2826 | G43: 0 | H43: 972 | I43: 6116 | J43: 844 | K43: 2014 | L43: 2524 | M43: 18832 | N43: 2616 | O43: 7792 | P43: 0 | Q43: =SUM(E43:P43) -> 44536
C44: FULFILMENT RATE | D44: % | E44: =IF(E42=0,"N/A",IF(ISERROR(E43/E42),0,(E43/E42))) -> N/A | F44: =IF(F42=0,"N/A",IF(ISERROR(F43/F42),0,(F43/F42))) -> 0.64110708 | G44: =IF(G42=0,"N/A",IF(ISERROR(G43/G42),0,(G43/G42))) -> N/A | H44: =IF(H42=0,"N/A",IF(ISERROR(H43/H42),0,(H43/H42))) -> 1 | I44: =IF(I42=0,"N/A",IF(ISERROR(I43/I42),0,(I43/I42))) -> 0.72705659 | J44: =IF(J42=0,"N/A",IF(ISERROR(J43/J42),0,(J43/J42))) -> 1 | K44: =IF(K42=0,"N/A",IF(ISERROR(K43/K42),0,(K43/K42))) -> 0.21836713 | L44: =IF(L42=0,"N/A",IF(ISERROR(L43/L42),0,(L43/L42))) -> 0.52019786 | ... Q44: =IF(Q42=0,"N/A",IF(ISERROR(Q43/Q42),0,(Q43/Q42))) -> 0.61117896
C46: NOTE: Due to timing differences between the original order being submitted and the order being invoiced, the fulfilment rate for the most recently completed period may not be representative of the final fulfilment rate for that period
C48: CALENDAR YTD ORDERS AND FULFILMENT SUMMARY - TESTERS
E49: JAN 2025 | F49: FEB 2025 | G49: MAR 2025 | H49: APR 2025 | I49: MAY 2025 | J49: JUN 2025 | K49: JUL 2025 | L49: AUG 2025 | M49: SEP 2025 | N49: OCT 2025 | O49: NOV 2025 | P49: DEC 2025 | Q49: YTD TOTAL
A50: Original Order Quantity | C50: ORDERED | D50: UNITS | E50: 0 | F50: 0 | G50: 0 | H50: 0 | I50: 0 | J50: 0 | K50: 0 | L50: 0 | M50: 0 | N50: 0 | O50: 0 | P50: 0 | Q50: =SUM(E50:P50) -> 0
A51: Accepted Order Quantity | C51: INVOICED | D51: UNITS | E51: 0 | F51: 0 | G51: 0 | H51: 0 | I51: 0 | J51: 0 | K51: 0 | L51: 0 | M51: 0 | N51: 0 | O51: 0 | P51: 0 | Q51: =SUM(E51:P51) -> 0
C52: FULFILMENT RATE | D52: % | E52: =IF(E50=0,"N/A",IF(ISERROR(E51/E50),0,(E51/E50))) -> N/A | F52: =IF(F50=0,"N/A",IF(ISERROR(F51/F50),0,(F51/F50))) -> N/A | G52: =IF(G50=0,"N/A",IF(ISERROR(G51/G50),0,(G51/G50))) -> N/A | H52: =IF(H50=0,"N/A",IF(ISERROR(H51/H50),0,(H51/H50))) -> N/A | I52: =IF(I50=0,"N/A",IF(ISERROR(I51/I50),0,(I51/I50))) -> N/A | J52: =IF(J50=0,"N/A",IF(ISERROR(J51/J50),0,(J51/J50))) -> N/A | K52: =IF(K50=0,"N/A",IF(ISERROR(K51/K50),0,(K51/K50))) -> N/A | L52: =IF(L50=0,"N/A",IF(ISERROR(L51/L50),0,(L51/L50))) -> N/A | ... Q52: =IF(Q50=0,"N/A",IF(ISERROR(Q51/Q50),0,(Q51/Q50))) -> N/A
A53: Accepted Order Quantity | C53: TOTAL INVOICED | D53: UNITS | E53: 0 | F53: 2826 | G53: 0 | H53: 972 | I53: 6116 | J53: 844 | K53: 2014 | L53: 2524 | M53: 18832 | N53: 2616 | O53: 7792 | P53: 0 | Q53: =SUM(E53:P53) -> 44536
C54: % TESTERS OF TOTAL INVOICED ITEMS | D54: % | E54: =IF(E51=0,"N/A",IF(ISERROR(E51/E53),0,(E51/E53))) -> N/A | F54: =IF(F51=0,"N/A",IF(ISERROR(F51/F53),0,(F51/F53))) -> N/A | G54: =IF(G51=0,"N/A",IF(ISERROR(G51/G53),0,(G51/G53))) -> N/A | H54: =IF(H51=0,"N/A",IF(ISERROR(H51/H53),0,(H51/H53))) -> N/A | I54: =IF(I51=0,"N/A",IF(ISERROR(I51/I53),0,(I51/I53))) -> N/A | J54: =IF(J51=0,"N/A",IF(ISERROR(J51/J53),0,(J51/J53))) -> N/A | K54: =IF(K51=0,"N/A",IF(ISERROR(K51/K53),0,(K51/K53))) -> N/A | L54: =IF(L51=0,"N/A",IF(ISERROR(L51/L53),0,(L51/L53))) -> N/A | ... Q54: =IF(Q51=0,"N/A",IF(ISERROR(Q51/Q53),0,(Q51/Q53))) -> N/A
C56: NOTE: 100% DIF brands will not have any testers fulfillment as live items will be converted to testers at the Mecca end
...

Sheet Appendix
A22: APPENDIX

Sheet Item Sales
A1: [Begin Format Range]
A2: =0 -> 0
A3: =1 -> 1
A4: =2 -> 2
A5: =3 -> 3
A6: D
A7: N
A8: P
A9: [End Format Range]
B10: Mecca:RPT Item Store Sales Monthly:2
B11: Currency | D11: Report AUD | H11: CUBE: | I11: Mecca:CTL Retail Calendar
B12: Company | D12: Mecca Concept Consolidated Excl Intl | H12: CTL Retail Calendar Measure | I12: Weeks in Month
B13: Sales Version | D13: Actual
B14: Trading As | D14: All Trading As Excl SIGLINE
B15: Lifestage | D15: All Lifestage
B16: DCS | D16: All DCS
B17: Brand | D17: =Master!$A$24 -> MERCI
B18: Store | D18: Total Stores by Concept Excl Non Store
B19: YTD Period | D19: =Master!$A$25 -> YTD 2025.M12 | E19: ="YTD "&(D20-1)&"."&RIGHT(D19,3) -> YTD 2024.M12 | F19: =MID(D19,5,8) -> 2025.M12 | G19: December
B20: Year | D20: =MID(D19,5,4) -> 2025
B21: Filter Reference: | D21: Order(Distinct({ }), ([Month].[YTD 2025.M12],[RPT Item Store Sales Monthly Measure].[Total Units Sold]), BDESC)
D23: MECCA BRANDS BRAND PERFORMANCE REPORT | AH23: =D17 -> MERCI
D24: YEAR TO DATE PRODUCT PERFORMANCE BY ITEM | AH24: =G19&" "&D20 -> December 2025
D26: YTD SALES PERFORMANCE BY ITEM (RANKED BY UNITS SOLD)
D27: YTD MONTH REF: | G27: 1 | H27: 1 | I27: 1 | J27: 1 | K27: 1 | L27: 1 | M27: 1 | N27: 1 | O27: 1 | P27: 1 | Q27: 1 | R27: 1 | S27: 1 | T27: 1 | U27: 1 | V27: 1 | W27: 1 | X27: 1 | Y27: 1 | Z27: 1 | AA27: 1 | AB27: 1 | AC27: 1 | AD27: 1
G28: =$D$20&".M01" -> 2025.M01 | H28: =$D$20&".M01" -> 2025.M01 | I28: =$D$20&".M02" -> 2025.M02 | J28: =$D$20&".M02" -> 2025.M02 | K28: =$D$20&".M03" -> 2025.M03 | L28: =$D$20&".M03" -> 2025.M03 | M28: =$D$20&".M04" -> 2025.M04 | N28: =$D$20&".M04" -> 2025.M04 | O28: =$D$20&".M05" -> 2025.M05 | P28: =$D$20&".M05" -> 2025.M05 | Q28: =$D$20&".M06" -> 2025.M06 | R28: =$D$20&".M06" -> 2025.M06 | S28: =$D$20&".M07" -> 2025.M07 | T28: =$D$20&".M07" -> 2025.M07 | U28: =$D$20&".M08" -> 2025.M08 | V28: =$D$20&".M08" -> 2025.M08 | W28: =$D$20&".M09" -> 2025.M09 | X28: =$D$20&".M09" -> 2025.M09 | Y28: =$D$20&".M10" -> 2025.M10 | Z28: =$D$20&".M10" -> 2025.M10 | AA28: =$D$20&".M11" -> 2025.M11 | AB28: =$D$20&".M11" -> 2025.M11 | AC28: =$D$20&".M12" -> 2025.M12 | AD28: =$D$20&".M12" -> 2025.M12 | AE28: =$D$19 -> YTD 2025.M12 | AF28: =$D$19 -> YTD 2025.M12 | AG28: =$D$19 -> YTD 2025.M12 | AH28: =$D$19 -> YTD 2025.M12
G29: Total Units Sold | H29: Total Store Sales | I29: Total Units Sold | J29: Total Store Sales | K29: Total Units Sold | L29: Total Store Sales | M29: Total Units Sold | N29: Total Store Sales | O29: Total Units Sold | P29: Total Store Sales | Q29: Total Units Sold | R29: Total Store Sales | S29: Total Units Sold | T29: Total Store Sales | U29: Total Units Sold | V29: Total Store Sales | W29: Total Units Sold | X29: Total Store Sales | Y29: Total Units Sold | Z29: Total Store Sales | AA29: Total Units Sold | AB29: Total Store Sales | AC29: Total Units Sold | AD29: Total Store Sales | AE29: Total Units Sold | AF29: % of Total Brand Units | AG29: Total Store Sales | AH29: % of Total Brand Sales
D30: RANK | E30: PRODUCT DESCRIPTION | F30: VENDOR ITEM CODE | G30: JAN 2025 | I30: FEB 2025 | K30: MAR 2025 | M30: APR 2025 | O30: MAY 2025 | Q30: JUN 2025 | S30: JUL 2025 | U30: AUG 2025 | W30: SEP 2025 | Y30: OCT 2025 | AA30: NOV 2025 | AC30: DEC 2025 | AE30: =LEFT(AE28,8) -> YTD 2025
G31: 4 | I31: 4 | K31: 5 | M31: 4 | O31: 4 | Q31: 5 | S31: 4 | U31: 4 | W31: 5 | Y31: 4 | AA31: 4 | AC31: 5 | AE31: 52
G32: UNITS | H32: $SALES | I32: UNITS | J32: $SALES | K32: UNITS | L32: $SALES | M32: UNITS | N32: $SALES | O32: UNITS | P32: $SALES | Q32: UNITS | R32: $SALES | S32: UNITS | T32: $SALES | U32: UNITS | V32: $SALES | W32: UNITS | X32: $SALES | Y32: UNITS | Z32: $SALES | AA32: UNITS | AB32: $SALES | AC32: UNITS | AD32: $SALES | AE32: UNITS | AF32: % UNITS | AG32: $SALES | AH32: % SALES
A33: N | B33: I-060352 | D33: =D32+1 -> 1 | E33: SPOT PATCHES | F33: MH-PATCH-24-22 | G33: 1686 | H33: 21498.96 | I33: 1558 | J33: 19900.4 | K33: 1777 | L33: 22700.56 | M33: 1703 | N33: 21840.52 | O33: 1319 | P33: 16820.98 | Q33: 1593 | R33: 20492.76 | S33: 1485 | T33: 19230.68 | U33: 1329 | V33: 17219.74 | W33: 1306 | X33: 17438.93 | Y33: 1005 | Z33: 13885.65 | AA33: 892 | AB33: 12340.41 | AC33: 2088 | AD33: 28947.3 | AE33: 17741 | AF33: 0.37828099 | AG33: 232316.89 | AH33: 0.43532073
A34: N | B34: I-040423 | D34: =D33+1 -> 2 | E34: HAND CLEANSING FLOWER POWER | F34: MH-GEL-30-FP-EU-19 | G34: 1050 | H34: 5333.06 | I34: 882 | J34: 4438.21 | K34: 922 | L34: 4641.46 | M34: 911 | N34: 4613.66 | O34: 811 | P34: 4225.38 | Q34: 1013 | R34: 6111.78 | S34: 282 | T34: 1701.13 | U34: 109 | V34: 653.98 | W34: 88 | X34: 539.39 | Y34: 11 | Z34: 65.04 | AA34: 2 | AB34: 12 | AC34: 12 | AD34: 72 | AE34: 6093 | AF34: 0.12991748 | AG34: 32407.09 | AH34: 0.06072515
A35: N | B35: I-040425 | D35: =D34+1 -> 3 | E35: HAND CLEANSING UNICORN | F35: MH-GEL-30-UE-EU-19 | G35: 917 | H35: 4666.39 | I35: 706 | J35: 3566.93 | K35: 867 | L35: 4328.05 | M35: 779 | N35: 3928.94 | O35: 524 | P35: 2676.27 | Q35: 260 | R35: 1569.81 | S35: 73 | T35: 439.79 | U35: 34 | V35: 205.92 | W35: 4 | X35: 21.6 | Y35: 0 | Z35: 0 | AA35: 0 | AB35: 0 | AC35: 1 | AD35: 6 | AE35: 4165 | AF35: 0.088807864 | AG35: 21409.7 | AH35: 0.040117988
A36: N | B36: I-060353 | D36: =D35+1 -> 4 | E36: BLOTTING PAPER | F36: MH-PM-50-22 | G36: 325 | H36: 4541.58 | I36: 70 | J36: 959.6 | K36: 21 | L36: 288.4 | M36: 0 | N36: 0 | O36: 290 | P36: 3996 | Q36: 274 | R36: 4099.07 | S36: 242 | T36: 3598.69 | U36: 232 | V36: 3472.88 | W36: 345 | X36: 5141.57 | Y36: 313 | Z36: 4704.59 | AA36: 254 | AB36: 3845.74 | AC36: 371 | AD36: 5591.05 | AE36: 2737 | AF36: 0.058359453 | AG36: 40239.17 | AH36: 0.075401082
A37: N | B37: I-040426 | D37: =D36+1 -> 5 | E37: HAND CLEANSING NAMASTE | F37: MH-GEL-30-NA-EU-19 | G37: 715 | H37: 3634.18 | I37: 523 | J37: 2637.01 | K37: 626 | L37: 3151.75 | M37: 284 | N37: 1441.75 | O37: 89 | P37: 456.99 | Q37: 74 | R37: 445.5 | S37: 31 | T37: 185.17 | U37: 6 | V37: 33.6 | W37: 0 | X37: 0 | Y37: 1 | Z37: 6.48 | AA37: -1 | AB37: -6 | AC37: 0 | AD37: 0 | AE37: 2348 | AF37: 0.050065033 | AG37: 11986.43 | AH37: 0.022460448
A38: N | B38: I-044748 | D38: =D37+1 -> 6 | E38: HAND CLEANS GLITTER FEVER | F38: MH-GEL-30-GF-EU-19 | G38: 370 | H38: 1883.17 | I38: 253 | J38: 1273.93 | K38: 315 | L38: 1581.55 | M38: 320 | N38: 1618.37 | O38: 296 | P38: 1517.15 | Q38: 398 | R38: 2395.23 | S38: 195 | T38: 1187.79 | U38: 60 | V38: 368.15 | W38: 68 | X38: 419.01 | Y38: 8 | Z38: 48 | AA38: 4 | AB38: 24 | AC38: 10 | AD38: 58.08 | AE38: 2297 | AF38: 0.04897759 | AG38: 12374.43 | AH38: 0.023187491
A39: N | B39: I-054934 | D39: =D38+1 -> 7 | E39: GLITTER SET | F39: MH-KIT-GLI-20 | G39: 41 | H39: 656.74 | I39: 95 | J39: 1521.86 | K39: 121 | L39: 1924.37 | M39: 97 | N39: 1546.81 | O39: 102 | P39: 1616.43 | Q39: 141 | R39: 2251.81 | S39: 160 | T39: 2553.18 | U39: 127 | V39: 2024 | W39: 209 | X39: 3409.6 | Y39: 185 | Z39: 3097.4 | AA39: 282 | AB39: 4775.61 | AC39: 350 | AD39: 6017.57 | AE39: 1910 | AF39: 0.040725815 | AG39: 31395.38 | AH39: 0.058829385
A40: N | B40: I-066437 | D40: =D39+1 -> 8 | E40: DEODORANT MOON 55G | F40: MH-DEO-MOON-55 | G40: 269 | H40: 4328.29 | I40: 262 | J40: 4185.92 | K40: 234 | L40: 3742.64 | M40: 170 | N40: 2692.76 | O40: 143 | P40: 2331.15 | Q40: 122 | R40: 2212.23 | S40: 47 | T40: 855.49 | U40: 32 | V40: 567.32 | W40: 26 | X40: 445.94 | Y40: 106 | Z40: 1795.93 | AA40: 109 | AB40: 1856.64 | AC40: 308 | AD40: 5228.91 | AE40: 1828 | AF40: 0.038977377 | AG40: 30243.22 | AH40: 0.056670441
A41: N | B41: I-040427 | D41: =D40+1 -> 9 | E41: HAND CLEANSING HELLO SUN | F41: MH-GEL-30-HS-EU-19 | G41: 357 | H41: 1803.62 | I41: 322 | J41: 1630.42 | K41: 360 | L41: 1815.46 | M41: 314 | N41: 1582.59 | O41: 191 | P41: 983.06 | Q41: 102 | R41: 614.82 | S41: 57 | T41: 345.93 | U41: 26 | V41: 153.6 | W41: 41 | X41: 248.15 | Y41: 10 | Z41: 61.44 | AA41: 3 | AB41: 18 | AC41: 11 | AD41: 66 | AE41: 1794 | AF41: 0.038252415 | AG41: 9323.09 | AH41: 0.01746982
A42: N | B42: I-066438 | D42: =D41+1 -> 10 | E42: DEODORANT SUN 55G | F42: MH-DEO-SUN-55 | G42: 128 | H42: 2073.8 | I42: 130 | J42: 2104.71 | K42: 122 | L42: 1952.4 | M42: 98 | N42: 1537.04 | O42: 70 | P42: 1137.37 | Q42: 101 | R42: 1821.25 | S42: 76 | T42: 1357.97 | U42: 97 | V42: 1765.39 | W42: 96 | X42: 1678.78 | Y42: 54 | Z42: 923.22 | AA42: 41 | AB42: 678.92 | AC42: 142 | AD42: 2414.9 | AE42: 1155 | AF42: 0.024627391 | AG42: 19445.75 | AH42: 0.036437893
...

Sheet Store Sales
A1: [Begin Format Range]
A2: =0 -> 0
A3: =1 -> 1
A4: =2 -> 2
A5: =3 -> 3
A6: D
A7: N
A8: A
A9: B
A10: C
A11: E
A12: F
A13: G
A14: [End Format Range]
D15: Mecca:RPT Item Store Sales Monthly:1
D17: Currency | E17: Report AUD | L17: CUBE: | M17: Mecca:CTL Retail Calendar
D18: Company | E18: Mecca Concept Consolidated Excl Intl | L18: CTL Retail Calendar Measure | M18: Weeks in Month
D19: Sales Version | E19: Actual
D20: Trading As | E20: All Trading As
D21: Lifestage | E21: All Lifestage
D22: DCS | E22: All DCS
D23: Brand | E23: =Master!A24 -> MERCI
D24: Item | E24: All Item
D25: YTD Period | E25: =Master!$A$25 -> YTD 2025.M12 | F25: ="YTD "&(E26-1)&"."&RIGHT(E25,3) -> YTD 2024.M12 | H25: =MID(E25,5,8) -> 2025.M12 | I25: December
D26: Year | E26: =MID(E25,5,4) -> 2025
D28: MECCA BRANDS BRAND PERFORMANCE REPORT | AF28: =E23 -> MERCI
D29: YTD STORE SALES PERFORMANCE REPORT | AF29: =$I$25&" "&$E$26 -> December 2025
H31: 1 | I31: 1 | J31: 1 | K31: 1 | L31: 1 | M31: 1 | N31: 1 | O31: 1 | P31: 1 | Q31: 1 | R31: 1 | S31: 1 | T31: 1 | U31: 1 | V31: 1 | W31: 1 | X31: 1 | Y31: 1 | Z31: 1 | AA31: 1 | AB31: 1 | AC31: 1 | AD31: 1 | AE31: 1
H32: =$E$26&".M01" -> 2025.M01 | I32: =$E$26&".M01" -> 2025.M01 | J32: =$E$26&".M02" -> 2025.M02 | K32: =$E$26&".M02" -> 2025.M02 | L32: =$E$26&".M03" -> 2025.M03 | M32: =$E$26&".M03" -> 2025.M03 | N32: =$E$26&".M04" -> 2025.M04 | O32: =$E$26&".M04" -> 2025.M04 | P32: =$E$26&".M05" -> 2025.M05 | Q32: =$E$26&".M05" -> 2025.M05 | R32: =$E$26&".M06" -> 2025.M06 | S32: =$E$26&".M06" -> 2025.M06 | T32: =$E$26&".M07" -> 2025.M07 | U32: =$E$26&".M07" -> 2025.M07 | V32: =$E$26&".M08" -> 2025.M08 | W32: =$E$26&".M08" -> 2025.M08 | X32: =$E$26&".M09" -> 2025.M09 | Y32: =$E$26&".M09" -> 2025.M09 | Z32: =$E$26&".M10" -> 2025.M10 | AA32: =$E$26&".M10" -> 2025.M10 | AB32: =$E$26&".M11" -> 2025.M11 | AC32: =$E$26&".M11" -> 2025.M11 | AD32: =$E$26&".M12" -> 2025.M12 | AE32: =$E$26&".M12" -> 2025.M12 | AF32: =$E$25 -> YTD 2025.M12 | AG32: =$E$25 -> YTD 2025.M12
H33: Total Store Sales | I33: Total Growth on LY | J33: Total Store Sales | K33: Total Growth on LY | L33: Total Store Sales | M33: Total Growth on LY | N33: Total Store Sales | O33: Total Growth on LY | P33: Total Store Sales | Q33: Total Growth on LY | R33: Total Store Sales | S33: Total Growth on LY | T33: Total Store Sales | U33: Total Growth on LY | V33: Total Store Sales | W33: Total Growth on LY | X33: Total Store Sales | Y33: Total Growth on LY | Z33: Total Store Sales | AA33: Total Growth on LY | AB33: Total Store Sales | AC33: Total Growth on LY | AD33: Total Store Sales | AE33: Total Growth on LY | AF33: Total Store Sales | AG33: Store % of Trading As Sales
H34: JAN 2025 | J34: FEB 2025 | L34: MAR 2025 | N34: APR 2025 | P34: MAY 2025 | R34: JUN 2025 | T34: JUL 2025 | V34: AUG 2025 | X34: SEP 2025 | Z34: OCT 2025 | AB34: NOV 2025 | AD34: DEC 2025 | AF34: =LEFT(AF32,8) -> YTD 2025
F35: # Weeks | H35: 4 | J35: 4 | L35: 5 | N35: 4 | P35: 4 | R35: 5 | T35: 4 | V35: 4 | X35: 5 | Z35: 4 | AB35: 4 | AD35: 5 | AF35: 52
H36: $ SALES | I36: % ON LY | J36: $ SALES | K36: % ON LY | L36: $ SALES | M36: % ON LY | N36: $ SALES | O36: % ON LY | P36: $ SALES | Q36: % ON LY | R36: $ SALES | S36: % ON LY | T36: $ SALES | U36: % ON LY | V36: $ SALES | W36: % ON LY | X36: $ SALES | Y36: % ON LY | Z36: $ SALES | AA36: % ON LY | AB36: $ SALES | AC36: % ON LY | AD36: $ SALES | AE36: % ON LY | AF36: $ SALES | AG36: % SHARE
A37: N | D37: M001 | E37: Cosmetica Toorak Rd | F37: =E37 -> Cosmetica Toorak Rd | H37: 0 | I37: 0 | J37: 0 | K37: 0 | L37: 0 | M37: 0 | N37: 0 | O37: 0 | P37: 0 | Q37: 0 | R37: 0 | S37: 0 | T37: 0 | U37: 0 | V37: 0 | W37: 0 | X37: 0 | Y37: -1 | Z37: 0 | AA37: 0 | AB37: 0 | AC37: 0 | AD37: 0 | AE37: 0 | AF37: 0 | AG37: 0
A38: N | D38: M004 | E38: Cosmetica Chadstone | F38: =E38 -> Cosmetica Chadstone | H38: 0 | I38: 0 | J38: 0 | K38: 0 | L38: 0 | M38: 0 | N38: 0 | O38: -1 | P38: 0 | Q38: 0 | R38: 0 | S38: 0 | T38: 0 | U38: 0 | V38: 0 | W38: 0 | X38: 0 | Y38: 0 | Z38: 0 | AA38: 0 | AB38: 0 | AC38: 0 | AD38: -17 | AE38: 0 | AF38: -17 | AG38: -3.1854991e-05
A39: N | D39: M008 | E39: Cosmetica Claremont | F39: =E39 -> Cosmetica Claremont | H39: -16 | I39: 0 | J39: 0 | K39: 0 | L39: 0 | M39: 0 | N39: 0 | O39: 0 | P39: 0 | Q39: 0 | R39: 0 | S39: 0 | T39: 0 | U39: 0 | V39: 0 | W39: 0 | X39: 0 | Y39: 0 | Z39: 0 | AA39: 0 | AB39: 0 | AC39: 0 | AD39: 0 | AE39: 0 | AF39: -16 | AG39: -2.9981168e-05
A40: N | D40: M013 | E40: Cosmetica Queens Plaza | F40: =E40 -> Cosmetica Queens Plaza | H40: 91 | I40: 0 | J40: 91 | K40: 6.5833333 | L40: 39 | M40: -0.4 | N40: 72.8 | O40: 0 | P40: 52 | Q40: 3 | R40: 130 | S40: 0.78571429 | T40: 52 | U40: -0.23076923 | V40: 52 | W40: 1 | X40: 53 | Y40: 0.35897436 | Z40: 42 | AA40: -0.46153846 | AB40: 0 | AC40: 0 | AD40: 84 | AE40: 2.2307692 | AF40: 758.8 | AG40: 0.0014218569
A41: N | D41: M020 | E41: Cosmetica Mosman | F41: =E41 -> Cosmetica Mosman | H41: 0 | I41: -1 | J41: 0 | K41: 0 | L41: 0 | M41: 0 | N41: 0 | O41: 0 | P41: 0 | Q41: 0 | R41: 0 | S41: 0 | T41: 0 | U41: 0 | V41: 0 | W41: 0 | X41: 0 | Y41: 0 | Z41: 0 | AA41: 0 | AB41: 0 | AC41: 0 | AD41: 0 | AE41: 0 | AF41: 0 | AG41: 0
A42: N | D42: M025 | E42: Cosmetica Armadale | F42: =E42 -> Cosmetica Armadale | H42: 0 | I42: 0 | J42: 0 | K42: 0 | L42: 0 | M42: 0 | N42: 0 | O42: 0 | P42: 0 | Q42: 0 | R42: 0 | S42: 0 | T42: 18 | U42: 0 | V42: 0 | W42: 0 | X42: 0 | Y42: 0 | Z42: 0 | AA42: 0 | AB42: 0 | AC42: 0 | AD42: 0 | AE42: 0 | AF42: 18 | AG42: 3.3728814e-05
A43: N | D43: M029 | E43: Cosmetica Carlton | F43: =E43 -> Cosmetica Carlton | H43: 0 | I43: 0 | J43: 0 | K43: 0 | L43: 0 | M43: 0 | N43: 0 | O43: 0 | P43: 18 | Q43: 0 | R43: 0 | S43: 0 | T43: 0 | U43: 0 | V43: 0 | W43: 0 | X43: 0 | Y43: 0 | Z43: 0 | AA43: 0 | AB43: 0 | AC43: 0 | AD43: 0 | AE43: 0 | AF43: 18 | AG43: 3.3728814e-05
...
